Workbook

Sheet 01
A1: Name | B1: PSP-Element | C1: Date TT.MM.JJJJ | D1: from hh:mm | E1: to hh:mm | F1: hours autom. calculated | G1: Project (mandatory) | H1: Topic (mandatory) | I1: Task Group (optional) | J1: Description (optional) | K1: Task ID
A2: LastName, FirstName | B2: 146300100109 | C2: 46023 | D2: 0.35416667 | E2: 0.6875 | F2: =+(E2-D2)*24 -> 8 | G2: 9O Off | H2: HO (Public) Holiday | J2: New Year's Day / Neujahr
A3: LastName, FirstName | B3: 146300100109 | C3: 46024 | D3: 0.58333333 | E3: 0.64583333 | F3: =+(E3-D3)*24 -> 1.5 | G3: 9M Misc | H3: OR Organization | J3: Update through Mails
A4: LastName, FirstName | B4: 146300100109 | D4: 0.64583333 | E4: 0.71875 | F4: =+(E4-D4)*24 -> 1.75 | G4: 1C RDM - RDM Classic | H4: DV Development | I4: IN Investigation | J4: Exxon Issue 1189 and ..90 | K4: 1189 | L4: =SUBTOTAL(9,$F$2:$F$235) -> 127.58333 | M4: Formula
A5: LastName, FirstName | B5: 146300100109 | C5: 46025 | D5: 0.35416667 | E5: 0.6875 | F5: =+(E5-D5)*24 -> 8 | G5: 9O Off | H5: HO (Public) Holiday | J5: Weekend / Wochenende
A6: LastName, FirstName | B6: 146300100109 | C6: 46026 | D6: 0.35416667 | E6: 0.6875 | F6: =+(E6-D6)*24 -> 8 | G6: 9O Off | H6: HO (Public) Holiday | J6: Weekend / Wochenende
A7: LastName, FirstName | B7: 146300100109 | C7: 46027 | D7: 0.34722222 | E7: 0.38194444 | F7: =+(E7-D7)*24 -> 0.83333333 | G7: 9M Misc | H7: OR Organization | J7: Start Systems, Email Check, Sorting of TODOs | L7: =SUMIF(G2:G259,Metadata!$A$6,F2:F259) -> 22.616667 | M7: 9M Misc
A8: LastName, FirstName | B8: 146300100109 | D8: 0.38194444 | E8: 0.47916667 | F8: =+(E8-D8)*24 -> 2.3333333 | G8: 1C RDM - RDM Classic | H8: DV Development | I8: IN Investigation | J8: Exxon Issue 1189 - Deep Dive | K8: 1189 | L8: =SUMIF(G2:G259,Metadata!$A$5,F2:F259) -> 80 | M8: 9O Off (incl. VA, IL, HO)
A9: LastName, FirstName | B9: 146300100109 | D9: 0.47916667 | E9: 0.51388889 | F9: =+(E9-D9)*24 -> 0.83333333 | G9: 1C RDM - RDM Classic | H9: OR Organization | I9: AL Alignment | J9: Sara, Farida, Mike Call - Listening In
A10: LastName, FirstName | B10: 146300100109 | D10: 0.53472222 | E10: 0.58333333 | F10: =+(E10-D10)*24 -> 1.1666667 | G10: 1C RDM - RDM Classic | H10: DV Development | I10: IN Investigation | J10: Exxon Issue 1189 - Deep Dive Continue | K10: 1189 | L10: =SUBTOTAL(9,F261:F264) -> 0 | M10: Sum (hours)
A11: LastName, FirstName | B11: 146300100109 | D11: 0.58333333 | E11: 0.70486111 | F11: =+(E11-D11)*24 -> 2.9166667 | G11: 1C RDM - RDM Classic | H11: OR Organization | I11: AL Alignment | J11: Mike Call Search Query | K11: 1189 | L11: =F266/Overview!$B$21 -> 0 | M11: Sum (days)
A12: LastName, FirstName | B12: 146300100109 | C12: 46028 | D12: 0.35416667 | E12: 0.6875 | F12: =+(E12-D12)*24 -> 8 | G12: 9O Off | H12: HO (Public) Holiday | J12: The Three Wise Men / Die Heiligen drei Könige
A13: LastName, FirstName | B13: 146300100109 | C13: 46029 | D13: 0.36458333 | E13: 0.375 | F13: =+(E13-D13)*24 -> 0.25 | G13: 9M Misc | H13: OR Organization | J13: Start Systems, Setup of Equipment
A14: LastName, FirstName | B14: 146300100109 | D14: 0.375 | E14: 0.46875 | F14: =+(E14-D14)*24 -> 2.25 | G14: 2C RDM C - RDM Cloud Ready | H14: DV Development | I14: AL Alignment | J14: Jean-Marc Update on Cloud Ready State | L14: =SUMIF(H2:H259,"VA Vacation",F2:F259) -> 0 | M14: Vacation (hours)
A15: LastName, FirstName | B15: 146300100109 | D15: 0.45833333 | E15: 0.51041667 | F15: =+(E15-D15)*24 -> 1.25 | G15: 1C RDM - RDM Classic | H15: DV Development | I15: IN Investigation | J15: Code Comprehension of Mikes Code | K15: 1189
A16: LastName, FirstName | B16: 146300100109 | D16: 0.53472222 | E16: 0.61111111 | F16: =+(E16-D16)*24 -> 1.8333333 | G16: 1C RDM - RDM Classic | H16: DV Development | I16: TE Testing and Quality | J16: Testing of Mikes Code | K16: 1189
A17: LastName, FirstName | B17: 146300100109 | D17: 0.61111111 | E17: 0.625 | F17: =+(E17-D17)*24 -> 0.33333333 | G17: 9M Misc | H17: OR Organization | I17: AL Alignment | J17: Quick 1:1 Michael <-> Maxi
A18: LastName, FirstName | B18: 146300100109 | D18: 0.625 | E18: 0.69791667 | F18: =+(E18-D18)*24 -> 1.75 | G18: 1C RDM - RDM Classic | H18: DV Development | I18: CO Coding | J18: Coding Adaptation for Characterstics aswell + Testing | K18: 1189
A19: LastName, FirstName | B19: 146300100109 | C19: 46030 | D19: 0.375 | E19: 0.41666667 | F19: =+(E19-D19)*24 -> 1 | G19: 2C RDM C - RDM Cloud Ready | H19: DV Development | I19: CO Coding | J19: Country 9903
A20: LastName, FirstName | B20: 146300100109 | D20: 0.41666667 | E20: 0.4375 | F20: =+(E20-D20)*24 -> 0.5 | G20: 9M Misc | H20: OR Organization | I20: AL Alignment | J20: Michael <-> Maxi
A21: LastName, FirstName | B21: 146300100109 | D21: 0.4375 | E21: 0.52083333 | F21: =+(E21-D21)*24 -> 2 | G21: 2C RDM C - RDM Cloud Ready | H21: DV Development | I21: CO Coding | J21: Country 9903
A22: LastName, FirstName | B22: 146300100109 | D22: 0.54166667 | E22: 0.66666667 | F22: =+(E22-D22)*24 -> 3 | G22: 2C RDM C - RDM Cloud Ready | H22: DV Development | I22: CO Coding | J22: Country 9903
A23: LastName, FirstName | B23: 146300100109 | D23: 0.66666667 | E23: 0.72222222 | F23: =+(E23-D23)*24 -> 1.3333333 | G23: 2C RDM C - RDM Cloud Ready | H23: OR Organization | I23: AL Alignment | J23: Cloud Ready Daily Alignment
A24: LastName, FirstName | B24: 146300100109 | C24: 46031 | D24: 0.375 | E24: 0.41666667 | F24: =+(E24-D24)*24 -> 1 | G24: 9M Misc | J24: Community Breakfast
A25: LastName, FirstName | B25: 146300100109 | D25: 0.41666667 | E25: 0.45833333 | F25: =+(E25-D25)*24 -> 1 | G25: 2C RDM C - RDM Cloud Ready | H25: DV Development | I25: IN Investigation | J25: Troubleshooting Eclipse after Update (AAAAARGH!!!)
A26: LastName, FirstName | B26: 146300100109 | D26: 0.45833333 | E26: 0.47916667 | F26: =+(E26-D26)*24 -> 0.5 | G26: 1C RDM - RDM Classic | H26: OR Organization | I26: AL Alignment | J26: Team Meating
A27: LastName, FirstName | B27: 146300100109 | D27: 0.47916667 | E27: 0.54861111 | F27: =+(E27-D27)*24 -> 1.6666667 | G27: 2C RDM C - RDM Cloud Ready | H27: DV Development | I27: CO Coding | J27: 9903 CDS Stack
A28: LastName, FirstName | B28: 146300100109 | D28: 0.56944444 | E28: 0.66666667 | F28: =+(E28-D28)*24 -> 2.3333333 | G28: 2C RDM C - RDM Cloud Ready | H28: DV Development | I28: CO Coding | J28: 9903 CDS Stack
A29: LastName, FirstName | B29: 146300100109 | D29: 0.66666667 | E29: 0.70833333 | F29: =+(E29-D29)*24 -> 1 | G29: 2C RDM C - RDM Cloud Ready | H29: OR Organization | I29: AL Alignment | J29: Cloud Ready Daily Alignment
A30: LastName, FirstName | B30: 146300100109 | C30: 46032 | D30: 0.35416667 | E30: 0.6875 | F30: =+(E30-D30)*24 -> 8 | G30: 9O Off | H30: HO (Public) Holiday | J30: Weekend / Wochenende
A31: LastName, FirstName | B31: 146300100109 | C31: 46033 | D31: 0.35416667 | E31: 0.6875 | F31: =+(E31-D31)*24 -> 8 | G31: 9O Off | H31: HO (Public) Holiday | J31: Weekend / Wochenende
A32: LastName, FirstName | B32: 146300100109 | C32: 46034 | D32: 0.35416667 | E32: 0.47916667 | F32: =+(E32-D32)*24 -> 3 | G32: 2C RDM C - RDM Cloud Ready | H32: DV Development | I32: CO Coding | J32: 9903 ABAP Stack
A33: LastName, FirstName | B33: 146300100109 | D33: 0.47916667 | E33: 0.48958333 | F33: =+(E33-D33)*24 -> 0.25 | G33: 2C RDM C - RDM Cloud Ready | H33: OR Organization | I33: AL Alignment | J33: Jean-Marc - View Cluster Maintanance
A34: LastName, FirstName | B34: 146300100109 | D34: 0.48958333 | E34: 0.5625 | F34: =+(E34-D34)*24 -> 1.75 | G34: 2C RDM C - RDM Cloud Ready | H34: DV Development | I34: IN Investigation | J34: Troubleshooting Process Step Blockage during Customizing
A35: LastName, FirstName | B35: 146300100109 | D35: 0.625 | E35: 0.67708333 | F35: =+(E35-D35)*24 -> 1.25 | G35: 2C RDM C - RDM Cloud Ready | H35: DV Development | I35: IN Investigation | J35: 9903 Process Chain
A36: LastName, FirstName | D36: 0.67708333 | E36: 0.71875 | F36: =+(E36-D36)*24 -> 1 | G36: 2C RDM C - RDM Cloud Ready | H36: OR Organization | I36: AL Alignment | J36: Cloud Ready Daily Alignment
A37: LastName, FirstName | C37: 46035 | D37: 0.36458333 | E37: 0.375 | F37: =+(E37-D37)*24 -> 0.25 | G37: 9M Misc | H37: OR Organization | J37: Timesheet Maintanance of last day - because of not pushed state
A38: LastName, FirstName | D38: 0.375 | E38: 0.39583333 | F38: =+(E38-D38)*24 -> 0.5 | G38: 1C RDM - RDM Classic | H38: OR Organization | I38: AL Alignment | J38: RDM Dev Topics (Short)
A39: LastName, FirstName | D39: 0.39583333 | E39: 0.4375 | F39: =+(E39-D39)*24 -> 1 | G39: 2C RDM C - RDM Cloud Ready | H39: DV Development | I39: CO Coding | J39: Auxilary Class, Saver Class
A40: LastName, FirstName | D40: 0.4375 | E40: 0.47916667 | F40: =+(E40-D40)*24 -> 1 | G40: 2C RDM C - RDM Cloud Ready | H40: OR Organization | I40: AL Alignment | J40: Cloud Ready SAP Alignment
...

Sheet 02
A1: Name | B1: PSP-Element | C1: Date TT.MM.JJJJ | D1: from hh:mm | E1: to hh:mm | F1: hours autom. calculated | G1: Project (mandatory) | H1: Topic (mandatory) | I1: Task Group (optional) | J1: Description (optional) | K1: Task ID
A2: LastName, FirstName | B2: 146300100109 | C2: 46054 | D2: 0.35416667 | E2: 0.6875 | F2: =+(E2-D2)*24 -> 8 | G2: 9O Off | H2: HO (Public) Holiday | J2: Weekend / Wochenende
A3: LastName, FirstName | B3: 146300100109 | C3: 46055 | D3: 0.35416667 | E3: 0.4375 | F3: =+(E3-D3)*24 -> 2 | G3: 9M Misc | H3: DV Development | J3: Ticket Tool, Mails, Start Systems, Replication of errors | K3: 1177, 1216
A4: LastName, FirstName | B4: 146300100109 | D4: 0.4375 | E4: 0.47916667 | F4: =+(E4-D4)*24 -> 1 | G4: 1C RDM - RDM Classic | H4: OR Organization | I4: AL Alignment | J4: Michael <-> Maxi
A5: LastName, FirstName | B5: 146300100109 | D5: 0.47916667 | E5: 0.51041667 | F5: =+(E5-D5)*24 -> 0.75 | G5: 1C RDM - RDM Classic | H5: DV Development | J5: Client Contact Mails | K5: 1177, 1216
A6: LastName, FirstName | B6: 146300100109 | D6: 0.53125 | E6: 0.625 | F6: =+(E6-D6)*24 -> 2.25 | G6: 1C RDM - RDM Classic | H6: DV Development | J6: Client Contact Mails | K6: 1177, 1216
A7: LastName, FirstName | B7: 146300100109 | D7: 0.625 | E7: 0.66666667 | F7: =+(E7-D7)*24 -> 1 | G7: 1C RDM - RDM Classic | H7: OR Organization | I7: AL Alignment | J7: Tester Meeting
A8: LastName, FirstName | B8: 146300100109 | D8: 0.66666667 | E8: 0.70833333 | F8: =+(E8-D8)*24 -> 1 | G8: 2C RDM C - RDM Cloud Ready | H8: OR Organization | I8: AL Alignment | J8: Cloud Ready Daily Alignment
A9: LastName, FirstName | C9: 46056 | D9: 0.35416667 | E9: 0.375 | F9: =+(E9-D9)*24 -> 0.5 | G9: 9M Misc | J9: Tool Dev
A10: LastName, FirstName | B10: 146300100109 | D10: 0.375 | E10: 0.41666667 | F10: =+(E10-D10)*24 -> 1 | G10: 1C RDM - RDM Classic | H10: OR Organization | I10: AL Alignment
A11: LastName, FirstName | B11: 146300100109 | D11: 0.41666667 | E11: 0.4375 | F11: =+(E11-D11)*24 -> 0.5 | G11: 1C RDM - RDM Classic | H11: OR Organization | J11: Tool Dev, Transport Management
A12: LastName, FirstName | B12: 146300100109 | D12: 0.4375 | E12: 0.45833333 | F12: =+(E12-D12)*24 -> 0.5 | G12: 2C RDM C - RDM Cloud Ready | H12: OR Organization | I12: AL Alignment | J12: Cloud Ready SAP alignment
A13: LastName, FirstName | B13: 146300100109 | D13: 0.45833333 | E13: 0.46875 | F13: =+(E13-D13)*24 -> 0.25 | G13: 9M Misc | J13: Time Sheet Maintanance
A14: LastName, FirstName | B14: 146300100109 | D14: 0.46875 | E14: 0.47916667 | F14: =+(E14-D14)*24 -> 0.25 | G14: 1C RDM - RDM Classic | H14: OR Organization | I14: AL Alignment | J14: Pre Bayer Call | K14: 1177
A15: LastName, FirstName | B15: 146300100109 | D15: 0.47916667 | E15: 0.5 | F15: =+(E15-D15)*24 -> 0.5 | G15: 1C RDM - RDM Classic | H15: OR Organization | I15: AL Alignment | J15: Bayer Call | K15: 1177
A16: LastName, FirstName | B16: 146300100109 | D16: 0.5 | E16: 0.52083333 | F16: =+(E16-D16)*24 -> 0.5 | G16: 1C RDM - RDM Classic | H16: OR Organization | I16: AL Alignment | J16: Günter <-> Maxi | K16: 625
A17: LastName, FirstName | B17: 146300100109 | D17: 0.54166667 | E17: 0.66666667 | F17: =+(E17-D17)*24 -> 3 | G17: 1C RDM - RDM Classic | H17: DV Development | I17: IN Investigation | J17: Code Comparison Bayer <-> ID1; Farida Call (quick); CLR Single Gov
A18: LastName, FirstName | B18: 146300100109 | D18: 0.66666667 | E18: 0.73611111 | F18: =+(E18-D18)*24 -> 1.6666667 | G18: 2C RDM C - RDM Cloud Ready | H18: OR Organization | I18: CO Coding | J18: Daily Cloud Ready Alignment - Successfully implementing Editable Keys for Texts
A19: LastName, FirstName | B19: 146300100109 | C19: 46057 | D19: 0.35416667 | E19: 0.5 | F19: =+(E19-D19)*24 -> 3.5 | G19: 2C RDM C - RDM Cloud Ready | H19: DV Development | I19: IN Investigation | J19: Activation Error Debugging
A20: LastName, FirstName | B20: 146300100109 | D20: 0.52083333 | E20: 0.57291667 | F20: =+(E20-D20)*24 -> 1.25 | G20: 2C RDM C - RDM Cloud Ready | H20: DV Development | I20: IN Investigation | J20: Activation Error Debugging
A21: LastName, FirstName | B21: 146300100109 | D21: 0.57291667 | E21: 0.58333333 | F21: =+(E21-D21)*24 -> 0.25 | G21: 1C RDM - RDM Classic | H21: OR Organization | I21: AL Alignment | J21: Quick Talk w. Michael about Open Prod. Hier. Tickets
A22: LastName, FirstName | B22: 146300100109 | D22: 0.58333333 | E22: 0.625 | F22: =+(E22-D22)*24 -> 1 | G22: 1C RDM - RDM Classic | H22: OR Organization | I22: IN Investigation | J22: Prod Hier Tickets - Sichtung
A23: LastName, FirstName | B23: 146300100109 | D23: 0.625 | E23: 0.66666667 | F23: =+(E23-D23)*24 -> 1 | G23: 1C RDM - RDM Classic | H23: OR Organization | I23: AL Alignment | J23: Tester Meeting
A24: LastName, FirstName | B24: 146300100109 | D24: 0.66666667 | E24: 0.73263889 | F24: =+(E24-D24)*24 -> 1.5833333 | G24: 2C RDM C - RDM Cloud Ready | H24: OR Organization | I24: AL Alignment | J24: Cloud Ready Daily Alignment
A25: LastName, FirstName | B25: 146300100109 | C25: 46058 | D25: 0.35416667 | E25: 0.375 | F25: =+(E25-D25)*24 -> 0.5 | G25: 1C RDM - RDM Classic | H25: OR Organization | J25: TODO | K25: 1162
A26: LastName, FirstName | B26: 146300100109 | D26: 0.375 | E26: 0.39583333 | F26: =+(E26-D26)*24 -> 0.5 | G26: 1C RDM - RDM Classic | H26: OR Organization | I26: AL Alignment | J26: TODO
A27: LastName, FirstName | B27: 146300100109 | D27: 0.39583333 | E27: 0.4375 | F27: =+(E27-D27)*24 -> 1 | G27: 1C RDM - RDM Classic | H27: DV Development | I27: IN Investigation | J27: TODO
A28: LastName, FirstName | B28: 146300100109 | D28: 0.4375 | E28: 0.45833333 | F28: =+(E28-D28)*24 -> 0.5 | G28: 2C RDM C - RDM Cloud Ready | H28: OR Organization | I28: AL Alignment | J28: TODO
A29: LastName, FirstName | B29: 146300100109 | D29: 0.45833333 | E29: 0.5625 | F29: =+(E29-D29)*24 -> 2.5 | G29: 1C RDM - RDM Classic | H29: DV Development | I29: IN Investigation | J29: TODO | K29: 1162
A30: LastName, FirstName | B30: 146300100109 | D30: 0.58333333 | E30: 0.60069444 | F30: =+(E30-D30)*24 -> 0.41666667 | G30: 1C RDM - RDM Classic | H30: OR Organization | J30: TODO
A31: LastName, FirstName | B31: 146300100109 | D31: 0.60069444 | E31: 0.6875 | F31: =+(E31-D31)*24 -> 2.0833333 | G31: 1C RDM - RDM Classic | H31: OR Organization | I31: IN Investigation | J31: TODO
A32: LastName, FirstName | B32: 146300100109 | C32: 46059 | D32: 0.35416667 | E32: 0.45833333 | F32: =+(E32-D32)*24 -> 2.5 | G32: 1C RDM - RDM Classic | H32: DV Development | I32: CO Coding | K32: 1216
A33: LastName, FirstName | B33: 146300100109 | D33: 0.45833333 | E33: 0.47916667 | F33: =+(E33-D33)*24 -> 0.5 | G33: 1C RDM - RDM Classic | H33: OR Organization | I33: AL Alignment | J33: Team Meeting
A34: LastName, FirstName | B34: 146300100109 | D34: 0.47916667 | E34: 0.52083333 | F34: =+(E34-D34)*24 -> 1 | G34: 1C RDM - RDM Classic | H34: OR Organization | I34: AL Alignment | J34: Michael <-> Maxi
A35: LastName, FirstName | B35: 146300100109 | D35: 0.52083333 | E35: 0.5625 | F35: =+(E35-D35)*24 -> 1 | G35: 1C RDM - RDM Classic | H35: DV Development | I35: IN Investigation | K35: 1222
A36: LastName, FirstName | B36: 146300100109 | D36: 0.60416667 | E36: 0.64583333 | F36: =+(E36-D36)*24 -> 1 | G36: 1C RDM - RDM Classic | H36: DV Development | I36: TE Testing and Quality | K36: 1216
A37: LastName, FirstName | B37: 146300100109 | D37: 0.66666667 | E37: 0.72916667 | F37: =+(E37-D37)*24 -> 1.5 | G37: 2C RDM C - RDM Cloud Ready | H37: OR Organization | I37: AL Alignment | J37: Cloud Ready Daily Alignment
A38: LastName, FirstName | B38: 146300100109 | C38: 46060 | D38: 0.35416667 | E38: 0.6875 | F38: =+(E38-D38)*24 -> 8 | G38: 9O Off | H38: HO (Public) Holiday | J38: Weekend / Wochenende
A39: LastName, FirstName | B39: 146300100109 | C39: 46061 | D39: 0.35416667 | E39: 0.6875 | F39: =+(E39-D39)*24 -> 8 | G39: 9O Off | H39: HO (Public) Holiday | J39: Weekend / Wochenende
A40: LastName, FirstName | B40: 146300100109 | C40: 46062 | D40: 0.35416667 | E40: 0.6875 | F40: =+(E40-D40)*24 -> 8 | G40: 9O Off | H40: VA Vacation | J40: Concert
...

Sheet 03
A1: Name | B1: PSP-Element | C1: Date TT.MM.JJJJ | D1: from hh:mm | E1: to hh:mm | F1: hours autom. calculated | G1: Project (mandatory) | H1: Topic (mandatory) | I1: Task Group (optional) | J1: Description (optional) | K1: Task ID
A2: LastName, FirstName | B2: 146300100109 | C2: 46082 | D2: 0.35416667 | E2: 0.6875 | F2: =+(E2-D2)*24 -> 8 | G2: 9O Off | H2: HO (Public) Holiday | J2: Weekend / Wochenende
A3: LastName, FirstName | B3: 146300100109 | C3: 46083 | F3: =+(E3-D3)*24 -> 0
A4: LastName, FirstName | B4: 146300100109 | C4: 46083 | F4: =+(E4-D4)*24 -> 0
A5: LastName, FirstName | B5: 146300100109 | C5: 46083 | F5: =+(E5-D5)*24 -> 0
A6: LastName, FirstName | B6: 146300100109 | C6: 46083 | F6: =+(E6-D6)*24 -> 0
A7: LastName, FirstName | B7: 146300100109 | C7: 46083 | F7: =+(E7-D7)*24 -> 0
A8: LastName, FirstName | B8: 146300100109 | C8: 46083 | F8: =+(E8-D8)*24 -> 0
A9: LastName, FirstName | C9: 46083 | F9: =+(E9-D9)*24 -> 0
A10: LastName, FirstName | B10: 146300100109 | C10: 46083 | F10: =+(E10-D10)*24 -> 0
A11: LastName, FirstName | B11: 146300100109 | C11: 46084 | F11: =+(E11-D11)*24 -> 0
A12: LastName, FirstName | B12: 146300100109 | C12: 46084 | F12: =+(E12-D12)*24 -> 0
A13: LastName, FirstName | B13: 146300100109 | C13: 46084 | F13: =+(E13-D13)*24 -> 0
A14: LastName, FirstName | B14: 146300100109 | C14: 46084 | F14: =+(E14-D14)*24 -> 0
A15: LastName, FirstName | B15: 146300100109 | C15: 46084 | F15: =+(E15-D15)*24 -> 0
A16: LastName, FirstName | B16: 146300100109 | C16: 46084 | F16: =+(E16-D16)*24 -> 0
A17: LastName, FirstName | B17: 146300100109 | C17: 46084 | F17: =+(E17-D17)*24 -> 0
A18: LastName, FirstName | B18: 146300100109 | C18: 46084 | F18: =+(E18-D18)*24 -> 0
A19: LastName, FirstName | B19: 146300100109 | C19: 46085 | F19: =+(E19-D19)*24 -> 0
A20: LastName, FirstName | B20: 146300100109 | C20: 46085 | F20: =+(E20-D20)*24 -> 0
A21: LastName, FirstName | B21: 146300100109 | C21: 46085 | F21: =+(E21-D21)*24 -> 0
... A42: LastName, FirstName | B42: 146300100109 | C42: 46087 | F42: =+(E42-D42)*24 -> 0
A43: LastName, FirstName | B43: 146300100109 | C43: 46088 | D43: 0.35416667 | E43: 0.6875 | F43: =+(E43-D43)*24 -> 8 | G43: 9O Off | H43: HO (Public) Holiday | J43: Weekend / Wochenende
A44: LastName, FirstName | B44: 146300100109 | C44: 46089 | D44: 0.35416667 | E44: 0.6875 | F44: =+(E44-D44)*24 -> 8 | G44: 9O Off | H44: HO (Public) Holiday | J44: Weekend / Wochenende
A45: LastName, FirstName | B45: 146300100109 | C45: 46090 | F45: =+(E45-D45)*24 -> 0
A46: LastName, FirstName | B46: 146300100109 | C46: 46090 | F46: =+(E46-D46)*24 -> 0
A47: LastName, FirstName | B47: 146300100109 | C47: 46090 | F47: =+(E47-D47)*24 -> 0
A48: LastName, FirstName | B48: 146300100109 | C48: 46090 | F48: =+(E48-D48)*24 -> 0
A49: LastName, FirstName | B49: 146300100109 | C49: 46090 | F49: =+(E49-D49)*24 -> 0
A50: LastName, FirstName | B50: 146300100109 | C50: 46090 | F50: =+(E50-D50)*24 -> 0
A51: LastName, FirstName | B51: 146300100109 | C51: 46090 | F51: =+(E51-D51)*24 -> 0
A52: LastName, FirstName | B52: 146300100109 | C52: 46090 | F52: =+(E52-D52)*24 -> 0
A53: LastName, FirstName | C53: 46091 | F53: =+(E53-D53)*24 -> 0
A54: LastName, FirstName | C54: 46091 | F54: =+(E54-D54)*24 -> 0
A55: LastName, FirstName | C55: 46091 | F55: =+(E55-D55)*24 -> 0
A56: LastName, FirstName | C56: 46091 | F56: =+(E56-D56)*24 -> 0
A57: LastName, FirstName | C57: 46091 | F57: =+(E57-D57)*24 -> 0
A58: LastName, FirstName | C58: 46091 | F58: =+(E58-D58)*24 -> 0
A59: LastName, FirstName | C59: 46091 | F59: =+(E59-D59)*24 -> 0
A60: LastName, FirstName | C60: 46091 | F60: =+(E60-D60)*24 -> 0
...

Sheet 04
A1: Name | B1: PSP-Element | C1: Date TT.MM.JJJJ | D1: from hh:mm | E1: to hh:mm | F1: hours autom. calculated | G1: Project (mandatory) | H1: Topic (mandatory) | I1: Task Group (optional) | J1: Description (optional) | K1: Task ID
A2: LastName, FirstName | B2: 146300100109 | C2: 46113 | F2: =+(E2-D2)*24 -> 0
A3: LastName, FirstName | B3: 146300100109 | C3: 46113 | F3: =+(E3-D3)*24 -> 0
A4: LastName, FirstName | B4: 146300100109 | C4: 46113 | F4: =+(E4-D4)*24 -> 0
A5: LastName, FirstName | B5: 146300100109 | C5: 46113 | F5: =+(E5-D5)*24 -> 0
A6: LastName, FirstName | B6: 146300100109 | C6: 46113 | F6: =+(E6-D6)*24 -> 0
A7: LastName, FirstName | B7: 146300100109 | C7: 46113 | F7: =+(E7-D7)*24 -> 0
A8: LastName, FirstName | B8: 146300100109 | C8: 46113 | F8: =+(E8-D8)*24 -> 0
A9: LastName, FirstName | C9: 46113 | F9: =+(E9-D9)*24 -> 0
A10: LastName, FirstName | B10: 146300100109 | C10: 46114 | F10: =+(E10-D10)*24 -> 0
A11: LastName, FirstName | B11: 146300100109 | C11: 46114 | F11: =+(E11-D11)*24 -> 0
A12: LastName, FirstName | B12: 146300100109 | C12: 46114 | F12: =+(E12-D12)*24 -> 0
A13: LastName, FirstName | B13: 146300100109 | C13: 46114 | F13: =+(E13-D13)*24 -> 0
A14: LastName, FirstName | B14: 146300100109 | C14: 46114 | F14: =+(E14-D14)*24 -> 0
A15: LastName, FirstName | B15: 146300100109 | C15: 46114 | F15: =+(E15-D15)*24 -> 0
A16: LastName, FirstName | B16: 146300100109 | C16: 46114 | F16: =+(E16-D16)*24 -> 0
A17: LastName, FirstName | B17: 146300100109 | C17: 46114 | F17: =+(E17-D17)*24 -> 0
A18: LastName, FirstName | B18: 146300100109 | C18: 46115 | D18: 0.35416667 | E18: 0.6875 | F18: =+(E18-D18)*24 -> 8 | G18: 9O Off | H18: HO (Public) Holiday | J18: Good Friday / Karfreitag
A19: LastName, FirstName | B19: 146300100109 | C19: 46116 | D19: 0.35416667 | E19: 0.6875 | F19: =+(E19-D19)*24 -> 8 | G19: 9O Off | H19: HO (Public) Holiday | J19: Weekend / Wochenende
A20: LastName, FirstName | B20: 146300100109 | C20: 46117 | D20: 0.35416667 | E20: 0.6875 | F20: =+(E20-D20)*24 -> 8 | G20: 9O Off | H20: HO (Public) Holiday | J20: Weekend / Wochenende
A21: LastName, FirstName | B21: 146300100109 | C21: 46118 | D21: 0.35416667 | E21: 0.6875 | F21: =+(E21-D21)*24 -> 8 | G21: 9O Off | H21: HO (Public) Holiday | J21: Easter Monday / Ostermontag
A22: LastName, FirstName | B22: 146300100109 | C22: 46119 | F22: =+(E22-D22)*24 -> 0
A23: LastName, FirstName | B23: 146300100109 | C23: 46119 | F23: =+(E23-D23)*24 -> 0
A24: LastName, FirstName | B24: 146300100109 | C24: 46119 | F24: =+(E24-D24)*24 -> 0
A25: LastName, FirstName | B25: 146300100109 | C25: 46119 | F25: =+(E25-D25)*24 -> 0
A26: LastName, FirstName | B26: 146300100109 | C26: 46119 | F26: =+(E26-D26)*24 -> 0
A27: LastName, FirstName | B27: 146300100109 | C27: 46119 | F27: =+(E27-D27)*24 -> 0
A28: LastName, FirstName | B28: 146300100109 | C28: 46119 | F28: =+(E28-D28)*24 -> 0
A29: LastName, FirstName | B29: 146300100109 | C29: 46119 | F29: =+(E29-D29)*24 -> 0
A30: LastName, FirstName | B30: 146300100109 | C30: 46120 | F30: =+(E30-D30)*24 -> 0
A31: LastName, FirstName | B31: 146300100109 | C31: 46120 | F31: =+(E31-D31)*24 -> 0
A32: LastName, FirstName | B32: 146300100109 | C32: 46120 | F32: =+(E32-D32)*24 -> 0
A33: LastName, FirstName | B33: 146300100109 | C33: 46120 | F33: =+(E33-D33)*24 -> 0
... A52: LastName, FirstName | B52: 146300100109 | C52: 46122 | F52: =+(E52-D52)*24 -> 0
A53: LastName, FirstName | C53: 46122 | F53: =+(E53-D53)*24 -> 0
A54: LastName, FirstName | C54: 46123 | D54: 0.35416667 | E54: 0.6875 | F54: =+(E54-D54)*24 -> 8 | G54: 9O Off | H54: HO (Public) Holiday | J54: Weekend / Wochenende
A55: LastName, FirstName | C55: 46124 | D55: 0.35416667 | E55: 0.6875 | F55: =+(E55-D55)*24 -> 8 | G55: 9O Off | H55: HO (Public) Holiday | J55: Weekend / Wochenende
A56: LastName, FirstName | C56: 46125 | F56: =+(E56-D56)*24 -> 0
A57: LastName, FirstName | C57: 46125 | F57: =+(E57-D57)*24 -> 0
A58: LastName, FirstName | C58: 46125 | F58: =+(E58-D58)*24 -> 0
...

Sheet 05
A1: Name | B1: PSP-Element | C1: Date TT.MM.JJJJ | D1: from hh:mm | E1: to hh:mm | F1: hours autom. calculated | G1: Project (mandatory) | H1: Topic (mandatory) | I1: Task Group (optional) | J1: Description (optional) | K1: Task ID
A2: LastName, FirstName | B2: 146300100109 | C2: 46143 | D2: 0.35416667 | E2: 0.6875 | F2: =+(E2-D2)*24 -> 8 | G2: 9O Off | H2: HO (Public) Holiday | J2: Labor Day / Tag der Arbeit
A3: LastName, FirstName | B3: 146300100109 | C3: 46144 | D3: 0.35416667 | E3: 0.6875 | F3: =+(E3-D3)*24 -> 8 | G3: 9O Off | H3: HO (Public) Holiday | J3: Weekend / Wochenende
A4: LastName, FirstName | B4: 146300100109 | C4: 46145 | D4: 0.35416667 | E4: 0.6875 | F4: =+(E4-D4)*24 -> 8 | G4: 9O Off | H4: HO (Public) Holiday | J4: Weekend / Wochenende
A5: LastName, FirstName | B5: 146300100109 | C5: 46146 | F5: =+(E5-D5)*24 -> 0
A6: LastName, FirstName | B6: 146300100109 | C6: 46146 | F6: =+(E6-D6)*24 -> 0
A7: LastName, FirstName | B7: 146300100109 | C7: 46146 | F7: =+(E7-D7)*24 -> 0
A8: LastName, FirstName | B8: 146300100109 | C8: 46146 | F8: =+(E8-D8)*24 -> 0
A9: LastName, FirstName | C9: 46146 | F9: =+(E9-D9)*24 -> 0
A10: LastName, FirstName | B10: 146300100109 | C10: 46146 | F10: =+(E10-D10)*24 -> 0
A11: LastName, FirstName | B11: 146300100109 | C11: 46146 | F11: =+(E11-D11)*24 -> 0
A12: LastName, FirstName | B12: 146300100109 | C12: 46146 | F12: =+(E12-D12)*24 -> 0
A13: LastName, FirstName | B13: 146300100109 | C13: 46147 | F13: =+(E13-D13)*24 -> 0
A14: LastName, FirstName | B14: 146300100109 | C14: 46147 | F14: =+(E14-D14)*24 -> 0
A15: LastName, FirstName | B15: 146300100109 | C15: 46147 | F15: =+(E15-D15)*24 -> 0
A16: LastName, FirstName | B16: 146300100109 | C16: 46147 | F16: =+(E16-D16)*24 -> 0
A17: LastName, FirstName | B17: 146300100109 | C17: 46147 | F17: =+(E17-D17)*24 -> 0
A18: LastName, FirstName | B18: 146300100109 | C18: 46147 | F18: =+(E18-D18)*24 -> 0
A19: LastName, FirstName | B19: 146300100109 | C19: 46147 | F19: =+(E19-D19)*24 -> 0
A20: LastName, FirstName | B20: 146300100109 | C20: 46147 | F20: =+(E20-D20)*24 -> 0
A21: LastName, FirstName | B21: 146300100109 | C21: 46148 | F21: =+(E21-D21)*24 -> 0
... A44: LastName, FirstName | B44: 146300100109 | C44: 46150 | F44: =+(E44-D44)*24 -> 0
A45: LastName, FirstName | B45: 146300100109 | C45: 46151 | D45: 0.35416667 | E45: 0.6875 | F45: =+(E45-D45)*24 -> 8 | G45: 9O Off | H45: HO (Public) Holiday | J45: Weekend / Wochenende
A46: LastName, FirstName | B46: 146300100109 | C46: 46152 | D46: 0.35416667 | E46: 0.6875 | F46: =+(E46-D46)*24 -> 8 | G46: 9O Off | H46: HO (Public) Holiday | J46: Weekend / Wochenende
A47: LastName, FirstName | B47: 146300100109 | C47: 46153 | F47: =+(E47-D47)*24 -> 0
A48: LastName, FirstName | B48: 146300100109 | C48: 46153 | F48: =+(E48-D48)*24 -> 0
A49: LastName, FirstName | B49: 146300100109 | C49: 46153 | F49: =+(E49-D49)*24 -> 0
A50: LastName, FirstName | B50: 146300100109 | C50: 46153 | F50: =+(E50-D50)*24 -> 0
A51: LastName, FirstName | B51: 146300100109 | C51: 46153 | F51: =+(E51-D51)*24 -> 0
A52: LastName, FirstName | B52: 146300100109 | C52: 46153 | F52: =+(E52-D52)*24 -> 0
A53: LastName, FirstName | C53: 46153 | F53: =+(E53-D53)*24 -> 0
A54: LastName, FirstName | C54: 46153 | F54: =+(E54-D54)*24 -> 0
A55: LastName, FirstName | C55: 46154 | F55: =+(E55-D55)*24 -> 0
A56: LastName, FirstName | C56: 46154 | F56: =+(E56-D56)*24 -> 0
A57: LastName, FirstName | C57: 46154 | F57: =+(E57-D57)*24 -> 0
A58: LastName, FirstName | C58: 46154 | F58: =+(E58-D58)*24 -> 0
A59: LastName, FirstName | C59: 46154 | F59: =+(E59-D59)*24 -> 0
A60: LastName, FirstName | C60: 46154 | F60: =+(E60-D60)*24 -> 0
A61: LastName, FirstName | C61: 46154 | F61: =+(E61-D61)*24 -> 0
A62: LastName, FirstName | C62: 46154 | F62: =+(E62-D62)*24 -> 0
...

Sheet 06
A1: Name | B1: PSP-Element | C1: Date TT.MM.JJJJ | D1: from hh:mm | E1: to hh:mm | F1: hours autom. calculated | G1: Project (mandatory) | H1: Topic (mandatory) | I1: Task Group (optional) | J1: Description (optional) | K1: Task ID
A2: LastName, FirstName | B2: 146300100109 | C2: 46174 | F2: =+(E2-D2)*24 -> 0
A3: LastName, FirstName | B3: 146300100109 | C3: 46174 | F3: =+(E3-D3)*24 -> 0
A4: LastName, FirstName | B4: 146300100109 | C4: 46174 | F4: =+(E4-D4)*24 -> 0
A5: LastName, FirstName | B5: 146300100109 | C5: 46174 | F5: =+(E5-D5)*24 -> 0
A6: LastName, FirstName | B6: 146300100109 | C6: 46174 | F6: =+(E6-D6)*24 -> 0
A7: LastName, FirstName | B7: 146300100109 | C7: 46174 | F7: =+(E7-D7)*24 -> 0
A8: LastName, FirstName | B8: 146300100109 | C8: 46174 | F8: =+(E8-D8)*24 -> 0
A9: LastName, FirstName | C9: 46174 | F9: =+(E9-D9)*24 -> 0
A10: LastName, FirstName | B10: 146300100109 | C10: 46174 | F10: =+(E10-D10)*24 -> 0
A11: LastName, FirstName | B11: 146300100109 | C11: 46175 | F11: =+(E11-D11)*24 -> 0
A12: LastName, FirstName | B12: 146300100109 | C12: 46175 | F12: =+(E12-D12)*24 -> 0
A13: LastName, FirstName | B13: 146300100109 | C13: 46175 | F13: =+(E13-D13)*24 -> 0
A14: LastName, FirstName | B14: 146300100109 | C14: 46175 | F14: =+(E14-D14)*24 -> 0
A15: LastName, FirstName | B15: 146300100109 | C15: 46175 | F15: =+(E15-D15)*24 -> 0
A16: LastName, FirstName | B16: 146300100109 | C16: 46175 | F16: =+(E16-D16)*24 -> 0
A17: LastName, FirstName | B17: 146300100109 | C17: 46175 | F17: =+(E17-D17)*24 -> 0
A18: LastName, FirstName | B18: 146300100109 | C18: 46175 | F18: =+(E18-D18)*24 -> 0
A19: LastName, FirstName | B19: 146300100109 | C19: 46175 | F19: =+(E19-D19)*24 -> 0
A20: LastName, FirstName | B20: 146300100109 | C20: 46176 | F20: =+(E20-D20)*24 -> 0
A21: LastName, FirstName | B21: 146300100109 | C21: 46176 | F21: =+(E21-D21)*24 -> 0
... A28: LastName, FirstName | B28: 146300100109 | C28: 46176 | F28: =+(E28-D28)*24 -> 0
A29: LastName, FirstName | B29: 146300100109 | C29: 46177 | D29: 0.35416667 | E29: 0.6875 | F29: =+(E29-D29)*24 -> 8 | G29: 9O Off | H29: HO (Public) Holiday | J29: Fronleichnam / Corpus Christi
A30: LastName, FirstName | B30: 146300100109 | C30: 46177 | F30: =+(E30-D30)*24 -> 0
A31: LastName, FirstName | B31: 146300100109 | C31: 46177 | F31: =+(E31-D31)*24 -> 0
A32: LastName, FirstName | B32: 146300100109 | C32: 46177 | F32: =+(E32-D32)*24 -> 0
A33: LastName, FirstName | B33: 146300100109 | C33: 46177 | F33: =+(E33-D33)*24 -> 0
A34: LastName, FirstName | B34: 146300100109 | C34: 46177 | F34: =+(E34-D34)*24 -> 0
A35: LastName, FirstName | B35: 146300100109 | C35: 46177 | F35: =+(E35-D35)*24 -> 0
A36: LastName, FirstName | B36: 146300100109 | C36: 46177 | F36: =+(E36-D36)*24 -> 0
A37: LastName, FirstName | B37: 146300100109 | C37: 46177 | F37: =+(E37-D37)*24 -> 0
A38: LastName, FirstName | B38: 146300100109 | C38: 46178 | F38: =+(E38-D38)*24 -> 0
A39: LastName, FirstName | B39: 146300100109 | C39: 46178 | F39: =+(E39-D39)*24 -> 0
A40: LastName, FirstName | B40: 146300100109 | C40: 46178 | F40: =+(E40-D40)*24 -> 0
A41: LastName, FirstName | B41: 146300100109 | C41: 46178 | F41: =+(E41-D41)*24 -> 0
... A46: LastName, FirstName | B46: 146300100109 | C46: 46178 | F46: =+(E46-D46)*24 -> 0
A47: LastName, FirstName | B47: 146300100109 | C47: 46179 | D47: 0.35416667 | E47: 0.6875 | F47: =+(E47-D47)*24 -> 8 | G47: 9O Off | H47: HO (Public) Holiday | J47: Weekend / Wochenende
A48: LastName, FirstName | B48: 146300100109 | C48: 46179
A49: LastName, FirstName | B49: 146300100109 | C49: 46179 | F49: =+(E49-D49)*24 -> 0
A50: LastName, FirstName | B50: 146300100109 | C50: 46179 | F50: =+(E50-D50)*24 -> 0
...

Sheet 07
A1: Name | B1: PSP-Element | C1: Date TT.MM.JJJJ | D1: from hh:mm | E1: to hh:mm | F1: hours autom. calculated | G1: Project (mandatory) | H1: Topic (mandatory) | I1: Task Group (optional) | J1: Description (optional) | K1: Task ID
A2: LastName, FirstName | B2: 146300100109 | C2: 46204 | F2: =+(E2-D2)*24 -> 0
A3: LastName, FirstName | B3: 146300100109 | C3: 46204 | F3: =+(E3-D3)*24 -> 0
A4: LastName, FirstName | B4: 146300100109 | C4: 46204 | F4: =+(E4-D4)*24 -> 0
A5: LastName, FirstName | B5: 146300100109 | C5: 46204 | F5: =+(E5-D5)*24 -> 0
A6: LastName, FirstName | B6: 146300100109 | C6: 46204 | F6: =+(E6-D6)*24 -> 0
A7: LastName, FirstName | B7: 146300100109 | C7: 46204 | F7: =+(E7-D7)*24 -> 0
A8: LastName, FirstName | B8: 146300100109 | C8: 46204 | F8: =+(E8-D8)*24 -> 0
A9: LastName, FirstName | C9: 46204 | F9: =+(E9-D9)*24 -> 0
A10: LastName, FirstName | B10: 146300100109 | C10: 46204 | F10: =+(E10-D10)*24 -> 0
A11: LastName, FirstName | B11: 146300100109 | C11: 46205 | F11: =+(E11-D11)*24 -> 0
A12: LastName, FirstName | B12: 146300100109 | C12: 46205 | F12: =+(E12-D12)*24 -> 0
A13: LastName, FirstName | B13: 146300100109 | C13: 46205 | F13: =+(E13-D13)*24 -> 0
A14: LastName, FirstName | B14: 146300100109 | C14: 46205 | F14: =+(E14-D14)*24 -> 0
A15: LastName, FirstName | B15: 146300100109 | C15: 46205 | F15: =+(E15-D15)*24 -> 0
A16: LastName, FirstName | B16: 146300100109 | C16: 46205 | F16: =+(E16-D16)*24 -> 0
A17: LastName, FirstName | B17: 146300100109 | C17: 46205 | F17: =+(E17-D17)*24 -> 0
A18: LastName, FirstName | B18: 146300100109 | C18: 46205 | F18: =+(E18-D18)*24 -> 0
A19: LastName, FirstName | B19: 146300100109 | C19: 46205 | F19: =+(E19-D19)*24 -> 0
A20: LastName, FirstName | B20: 146300100109 | C20: 46206 | F20: =+(E20-D20)*24 -> 0
A21: LastName, FirstName | B21: 146300100109 | C21: 46206 | F21: =+(E21-D21)*24 -> 0
... A28: LastName, FirstName | B28: 146300100109 | C28: 46206 | F28: =+(E28-D28)*24 -> 0
A29: LastName, FirstName | B29: 146300100109 | C29: 46207 | D29: 0.35416667 | E29: 0.6875 | F29: =+(E29-D29)*24 -> 8 | G29: 9O Off | H29: HO (Public) Holiday | J29: Weekend / Wochenende
A30: LastName, FirstName | B30: 146300100109 | C30: 46207
A31: LastName, FirstName | B31: 146300100109 | C31: 46207 | F31: =+(E31-D31)*24 -> 0
A32: LastName, FirstName | B32: 146300100109 | C32: 46207 | F32: =+(E32-D32)*24 -> 0
A33: LastName, FirstName | B33: 146300100109 | C33: 46207 | F33: =+(E33-D33)*24 -> 0
A34: LastName, FirstName | B34: 146300100109 | C34: 46207 | F34: =+(E34-D34)*24 -> 0
A35: LastName, FirstName | B35: 146300100109 | C35: 46207 | F35: =+(E35-D35)*24 -> 0
A36: LastName, FirstName | B36: 146300100109 | C36: 46207 | F36: =+(E36-D36)*24 -> 0
A37: LastName, FirstName | B37: 146300100109 | C37: 46207 | F37: =+(E37-D37)*24 -> 0
A38: LastName, FirstName | B38: 146300100109 | C38: 46208 | D38: 0.35416667 | E38: 0.6875 | F38: =+(E38-D38)*24 -> 8 | G38: 9O Off | H38: HO (Public) Holiday | J38: Weekend / Wochenende
A39: LastName, FirstName | B39: 146300100109 | C39: 46208 | F39: =+(E39-D39)*24 -> 0
A40: LastName, FirstName | B40: 146300100109 | C40: 46208 | F40: =+(E40-D40)*24 -> 0
A41: LastName, FirstName | B41: 146300100109 | C41: 46208 | F41: =+(E41-D41)*24 -> 0
A42: LastName, FirstName | B42: 146300100109 | C42: 46208 | F42: =+(E42-D42)*24 -> 0
A43: LastName, FirstName | B43: 146300100109 | C43: 46208 | F43: =+(E43-D43)*24 -> 0
A44: LastName, FirstName | B44: 146300100109 | C44: 46208 | F44: =+(E44-D44)*24 -> 0
A45: LastName, FirstName | B45: 146300100109 | C45: 46208 | F45: =+(E45-D45)*24 -> 0
A46: LastName, FirstName | B46: 146300100109 | C46: 46208 | F46: =+(E46-D46)*24 -> 0
...

Sheet 08
A1: Name | B1: PSP-Element | C1: Date TT.MM.JJJJ | D1: from hh:mm | E1: to hh:mm | F1: hours autom. calculated | G1: Project (mandatory) | H1: Topic (mandatory) | I1: Task Group (optional) | J1: Description (optional) | K1: Task ID
A2: LastName, FirstName | B2: 146300100109 | C2: 46235 | D2: 0.35416667 | E2: 0.6875 | F2: =+(E2-D2)*24 -> 8 | G2: 9O Off | H2: HO (Public) Holiday | J2: Weekend / Wochenende
A3: LastName, FirstName | B3: 146300100109 | C3: 46235
A4: LastName, FirstName | B4: 146300100109 | C4: 46235 | F4: =+(E4-D4)*24 -> 0
A5: LastName, FirstName | B5: 146300100109 | C5: 46235 | F5: =+(E5-D5)*24 -> 0
A6: LastName, FirstName | B6: 146300100109 | C6: 46235 | F6: =+(E6-D6)*24 -> 0
A7: LastName, FirstName | B7: 146300100109 | C7: 46235 | F7: =+(E7-D7)*24 -> 0
A8: LastName, FirstName | B8: 146300100109 | C8: 46235 | F8: =+(E8-D8)*24 -> 0
A9: LastName, FirstName | C9: 46235 | F9: =+(E9-D9)*24 -> 0
A10: LastName, FirstName | B10: 146300100109 | C10: 46235 | F10: =+(E10-D10)*24 -> 0
A11: LastName, FirstName | B11: 146300100109 | C11: 46236 | D11: 0.35416667 | E11: 0.6875 | F11: =+(E11-D11)*24 -> 8 | G11: 9O Off | H11: HO (Public) Holiday | J11: Weekend / Wochenende
A12: LastName, FirstName | B12: 146300100109 | C12: 46236 | F12: =+(E12-D12)*24 -> 0
A13: LastName, FirstName | B13: 146300100109 | C13: 46236 | F13: =+(E13-D13)*24 -> 0
A14: LastName, FirstName | B14: 146300100109 | C14: 46236 | F14: =+(E14-D14)*24 -> 0
A15: LastName, FirstName | B15: 146300100109 | C15: 46236 | F15: =+(E15-D15)*24 -> 0
A16: LastName, FirstName | B16: 146300100109 | C16: 46236 | F16: =+(E16-D16)*24 -> 0
A17: LastName, FirstName | B17: 146300100109 | C17: 46236 | F17: =+(E17-D17)*24 -> 0
A18: LastName, FirstName | B18: 146300100109 | C18: 46236 | F18: =+(E18-D18)*24 -> 0
A19: LastName, FirstName | B19: 146300100109 | C19: 46236 | F19: =+(E19-D19)*24 -> 0
A20: LastName, FirstName | B20: 146300100109 | C20: 46237 | F20: =+(E20-D20)*24 -> 0
A21: LastName, FirstName | B21: 146300100109 | C21: 46237 | F21: =+(E21-D21)*24 -> 0
A22: LastName, FirstName | B22: 146300100109 | C22: 46237 | F22: =+(E22-D22)*24 -> 0
A23: LastName, FirstName | B23: 146300100109 | C23: 46237 | F23: =+(E23-D23)*24 -> 0
... A52: LastName, FirstName | B52: 146300100109 | C52: 46240 | F52: =+(E52-D52)*24 -> 0
A53: LastName, FirstName | C53: 46240 | F53: =+(E53-D53)*24 -> 0
A54: LastName, FirstName | C54: 46240 | F54: =+(E54-D54)*24 -> 0
A55: LastName, FirstName | C55: 46240 | F55: =+(E55-D55)*24 -> 0
A56: LastName, FirstName | C56: 46241 | F56: =+(E56-D56)*24 -> 0
A57: LastName, FirstName | C57: 46241 | F57: =+(E57-D57)*24 -> 0
A58: LastName, FirstName | C58: 46241 | F58: =+(E58-D58)*24 -> 0
A59: LastName, FirstName | C59: 46241 | F59: =+(E59-D59)*24 -> 0
A60: LastName, FirstName | C60: 46241 | F60: =+(E60-D60)*24 -> 0
A61: LastName, FirstName | C61: 46241 | F61: =+(E61-D61)*24 -> 0
A62: LastName, FirstName | C62: 46241 | F62: =+(E62-D62)*24 -> 0
A63: LastName, FirstName | C63: 46241 | F63: =+(E63-D63)*24 -> 0
A64: LastName, FirstName | C64: 46241 | F64: =+(E64-D64)*24 -> 0
A65: LastName, FirstName | C65: 46242 | D65: 0.35416667 | E65: 0.6875 | F65: =+(E65-D65)*24 -> 8 | G65: 9O Off | H65: HO (Public) Holiday | J65: Weekend / Wochenende
A66: LastName, FirstName | C66: 46242
A67: LastName, FirstName | C67: 46242 | F67: =+(E67-D67)*24 -> 0
A68: LastName, FirstName | C68: 46242 | F68: =+(E68-D68)*24 -> 0
...

Sheet 09
A1: Name | B1: PSP-Element | C1: Date TT.MM.JJJJ | D1: from hh:mm | E1: to hh:mm | F1: hours autom. calculated | G1: Project (mandatory) | H1: Topic (mandatory) | I1: Task Group (optional) | J1: Description (optional) | K1: Task ID
A2: LastName, FirstName | B2: 146300100109 | C2: 46266 | F2: =+(E2-D2)*24 -> 0
A3: LastName, FirstName | B3: 146300100109 | C3: 46266 | F3: =+(E3-D3)*24 -> 0
A4: LastName, FirstName | B4: 146300100109 | C4: 46266 | F4: =+(E4-D4)*24 -> 0
A5: LastName, FirstName | B5: 146300100109 | C5: 46266 | F5: =+(E5-D5)*24 -> 0
A6: LastName, FirstName | B6: 146300100109 | C6: 46266 | F6: =+(E6-D6)*24 -> 0
A7: LastName, FirstName | B7: 146300100109 | C7: 46266 | F7: =+(E7-D7)*24 -> 0
A8: LastName, FirstName | B8: 146300100109 | C8: 46266 | F8: =+(E8-D8)*24 -> 0
A9: LastName, FirstName | C9: 46266 | F9: =+(E9-D9)*24 -> 0
A10: LastName, FirstName | B10: 146300100109 | C10: 46266 | F10: =+(E10-D10)*24 -> 0
A11: LastName, FirstName | B11: 146300100109 | C11: 46267 | F11: =+(E11-D11)*24 -> 0
A12: LastName, FirstName | B12: 146300100109 | C12: 46267 | F12: =+(E12-D12)*24 -> 0
A13: LastName, FirstName | B13: 146300100109 | C13: 46267 | F13: =+(E13-D13)*24 -> 0
A14: LastName, FirstName | B14: 146300100109 | C14: 46267 | F14: =+(E14-D14)*24 -> 0
A15: LastName, FirstName | B15: 146300100109 | C15: 46267 | F15: =+(E15-D15)*24 -> 0
A16: LastName, FirstName | B16: 146300100109 | C16: 46267 | F16: =+(E16-D16)*24 -> 0
A17: LastName, FirstName | B17: 146300100109 | C17: 46267 | F17: =+(E17-D17)*24 -> 0
A18: LastName, FirstName | B18: 146300100109 | C18: 46267 | F18: =+(E18-D18)*24 -> 0
A19: LastName, FirstName | B19: 146300100109 | C19: 46267 | F19: =+(E19-D19)*24 -> 0
A20: LastName, FirstName | B20: 146300100109 | C20: 46268 | F20: =+(E20-D20)*24 -> 0
A21: LastName, FirstName | B21: 146300100109 | C21: 46268 | F21: =+(E21-D21)*24 -> 0
... A37: LastName, FirstName | B37: 146300100109 | C37: 46269 | F37: =+(E37-D37)*24 -> 0
A38: LastName, FirstName | B38: 146300100109 | C38: 46270 | D38: 0.35416667 | E38: 0.6875 | F38: =+(E38-D38)*24 -> 8 | G38: 9O Off | H38: HO (Public) Holiday | J38: Weekend / Wochenende
A39: LastName, FirstName | B39: 146300100109 | C39: 46270
A40: LastName, FirstName | B40: 146300100109 | C40: 46270 | F40: =+(E40-D40)*24 -> 0
A41: LastName, FirstName | B41: 146300100109 | C41: 46270 | F41: =+(E41-D41)*24 -> 0
A42: LastName, FirstName | B42: 146300100109 | C42: 46270 | F42: =+(E42-D42)*24 -> 0
A43: LastName, FirstName | B43: 146300100109 | C43: 46270 | F43: =+(E43-D43)*24 -> 0
A44: LastName, FirstName | B44: 146300100109 | C44: 46270 | F44: =+(E44-D44)*24 -> 0
A45: LastName, FirstName | B45: 146300100109 | C45: 46270 | F45: =+(E45-D45)*24 -> 0
A46: LastName, FirstName | B46: 146300100109 | C46: 46270 | F46: =+(E46-D46)*24 -> 0
A47: LastName, FirstName | B47: 146300100109 | C47: 46271 | D47: 0.35416667 | E47: 0.6875 | F47: =+(E47-D47)*24 -> 8 | G47: 9O Off | H47: HO (Public) Holiday | J47: Weekend / Wochenende
A48: LastName, FirstName | B48: 146300100109 | C48: 46271 | F48: =+(E48-D48)*24 -> 0
A49: LastName, FirstName | B49: 146300100109 | C49: 46271 | F49: =+(E49-D49)*24 -> 0
A50: LastName, FirstName | B50: 146300100109 | C50: 46271 | F50: =+(E50-D50)*24 -> 0
A51: LastName, FirstName | B51: 146300100109 | C51: 46271 | F51: =+(E51-D51)*24 -> 0
A52: LastName, FirstName | B52: 146300100109 | C52: 46271 | F52: =+(E52-D52)*24 -> 0
A53: LastName, FirstName | C53: 46271 | F53: =+(E53-D53)*24 -> 0
A54: LastName, FirstName | C54: 46271 | F54: =+(E54-D54)*24 -> 0
A55: LastName, FirstName | C55: 46271 | F55: =+(E55-D55)*24 -> 0
...

Sheet 10
A1: Name | B1: PSP-Element | C1: Date TT.MM.JJJJ | D1: from hh:mm | E1: to hh:mm | F1: hours autom. calculated | G1: Project (mandatory) | H1: Topic (mandatory) | I1: Task Group (optional) | J1: Description (optional) | K1: Task ID
A2: LastName, FirstName | B2: 146300100109 | C2: 46296 | F2: =+(E2-D2)*24 -> 0
A3: LastName, FirstName | B3: 146300100109 | C3: 46296 | F3: =+(E3-D3)*24 -> 0
A4: LastName, FirstName | B4: 146300100109 | C4: 46296 | F4: =+(E4-D4)*24 -> 0
A5: LastName, FirstName | B5: 146300100109 | C5: 46296 | F5: =+(E5-D5)*24 -> 0
A6: LastName, FirstName | B6: 146300100109 | C6: 46296 | F6: =+(E6-D6)*24 -> 0
A7: LastName, FirstName | B7: 146300100109 | C7: 46296 | F7: =+(E7-D7)*24 -> 0
A8: LastName, FirstName | B8: 146300100109 | C8: 46296 | F8: =+(E8-D8)*24 -> 0
A9: LastName, FirstName | C9: 46296 | F9: =+(E9-D9)*24 -> 0
A10: LastName, FirstName | B10: 146300100109 | C10: 46296 | F10: =+(E10-D10)*24 -> 0
A11: LastName, FirstName | B11: 146300100109 | C11: 46297 | F11: =+(E11-D11)*24 -> 0
A12: LastName, FirstName | B12: 146300100109 | C12: 46297 | F12: =+(E12-D12)*24 -> 0
A13: LastName, FirstName | B13: 146300100109 | C13: 46297 | F13: =+(E13-D13)*24 -> 0
A14: LastName, FirstName | B14: 146300100109 | C14: 46297 | F14: =+(E14-D14)*24 -> 0
A15: LastName, FirstName | B15: 146300100109 | C15: 46297 | F15: =+(E15-D15)*24 -> 0
A16: LastName, FirstName | B16: 146300100109 | C16: 46297 | F16: =+(E16-D16)*24 -> 0
A17: LastName, FirstName | B17: 146300100109 | C17: 46297 | F17: =+(E17-D17)*24 -> 0
A18: LastName, FirstName | B18: 146300100109 | C18: 46297 | F18: =+(E18-D18)*24 -> 0
A19: LastName, FirstName | B19: 146300100109 | C19: 46297 | F19: =+(E19-D19)*24 -> 0
A20: LastName, FirstName | B20: 146300100109 | C20: 46298 | D20: 0.35416667 | E20: 0.6875 | F20: =+(E20-D20)*24 -> 8 | G20: 9O Off | H20: HO (Public) Holiday | J20: German Unity Day / Tag der Deutschen Einheit
A21: LastName, FirstName | B21: 146300100109 | C21: 46298 | F21: =+(E21-D21)*24 -> 0
A22: LastName, FirstName | B22: 146300100109 | C22: 46298 | F22: =+(E22-D22)*24 -> 0
A23: LastName, FirstName | B23: 146300100109 | C23: 46298 | F23: =+(E23-D23)*24 -> 0
A24: LastName, FirstName | B24: 146300100109 | C24: 46298 | F24: =+(E24-D24)*24 -> 0
A25: LastName, FirstName | B25: 146300100109 | C25: 46298 | F25: =+(E25-D25)*24 -> 0
A26: LastName, FirstName | B26: 146300100109 | C26: 46298 | F26: =+(E26-D26)*24 -> 0
A27: LastName, FirstName | B27: 146300100109 | C27: 46298 | F27: =+(E27-D27)*24 -> 0
A28: LastName, FirstName | B28: 146300100109 | C28: 46298 | F28: =+(E28-D28)*24 -> 0
A29: LastName, FirstName | B29: 146300100109 | C29: 46299 | D29: 0.35416667 | E29: 0.6875 | F29: =+(E29-D29)*24 -> 8 | G29: 9O Off | H29: HO (Public) Holiday | J29: Weekend / Wochenende
A30: LastName, FirstName | B30: 146300100109 | C30: 46299
A31: LastName, FirstName | B31: 146300100109 | C31: 46299 | F31: =+(E31-D31)*24 -> 0
A32: LastName, FirstName | B32: 146300100109 | C32: 46299 | F32: =+(E32-D32)*24 -> 0
A33: LastName, FirstName | B33: 146300100109 | C33: 46299 | F33: =+(E33-D33)*24 -> 0
A34: LastName, FirstName | B34: 146300100109 | C34: 46299 | F34: =+(E34-D34)*24 -> 0
A35: LastName, FirstName | B35: 146300100109 | C35: 46299 | F35: =+(E35-D35)*24 -> 0
A36: LastName, FirstName | B36: 146300100109 | C36: 46299 | F36: =+(E36-D36)*24 -> 0
A37: LastName, FirstName | B37: 146300100109 | C37: 46299 | F37: =+(E37-D37)*24 -> 0
A38: LastName, FirstName | B38: 146300100109 | C38: 46300
A39: LastName, FirstName | B39: 146300100109 | C39: 46300 | F39: =+(E39-D39)*24 -> 0
A40: LastName, FirstName | B40: 146300100109 | C40: 46300 | F40: =+(E40-D40)*24 -> 0
...

Sheet 11
A1: Name | B1: PSP-Element | C1: Date TT.MM.JJJJ | D1: from hh:mm | E1: to hh:mm | F1: hours autom. calculated | G1: Project (mandatory) | H1: Topic (mandatory) | I1: Task Group (optional) | J1: Description (optional) | K1: Task ID
A2: LastName, FirstName | B2: 146300100109 | C2: 46327 | D2: 0.35416667 | E2: 0.6875 | F2: =+(E2-D2)*24 -> 8 | G2: 9O Off | H2: HO (Public) Holiday | J2: All Saints Day / Allerheiligen
A3: LastName, FirstName | B3: 146300100109 | C3: 46327
A4: LastName, FirstName | B4: 146300100109 | C4: 46327 | F4: =+(E4-D4)*24 -> 0
A5: LastName, FirstName | B5: 146300100109 | C5: 46327 | F5: =+(E5-D5)*24 -> 0
A6: LastName, FirstName | B6: 146300100109 | C6: 46327 | F6: =+(E6-D6)*24 -> 0
A7: LastName, FirstName | B7: 146300100109 | C7: 46327 | F7: =+(E7-D7)*24 -> 0
A8: LastName, FirstName | B8: 146300100109 | C8: 46327 | F8: =+(E8-D8)*24 -> 0
A9: LastName, FirstName | C9: 46327 | F9: =+(E9-D9)*24 -> 0
A10: LastName, FirstName | B10: 146300100109 | C10: 46327 | F10: =+(E10-D10)*24 -> 0
A11: LastName, FirstName | B11: 146300100109 | C11: 46328 | D11: 0.35416667 | E11: 0.6875 | F11: =+(E11-D11)*24 -> 8 | G11: 9O Off | H11: HO (Public) Holiday | J11: Weekend / Wochenende
A12: LastName, FirstName | B12: 146300100109 | C12: 46328 | F12: =+(E12-D12)*24 -> 0
A13: LastName, FirstName | B13: 146300100109 | C13: 46328 | F13: =+(E13-D13)*24 -> 0
A14: LastName, FirstName | B14: 146300100109 | C14: 46328 | F14: =+(E14-D14)*24 -> 0
A15: LastName, FirstName | B15: 146300100109 | C15: 46328 | F15: =+(E15-D15)*24 -> 0
A16: LastName, FirstName | B16: 146300100109 | C16: 46328 | F16: =+(E16-D16)*24 -> 0
A17: LastName, FirstName | B17: 146300100109 | C17: 46328 | F17: =+(E17-D17)*24 -> 0
A18: LastName, FirstName | B18: 146300100109 | C18: 46328 | F18: =+(E18-D18)*24 -> 0
A19: LastName, FirstName | B19: 146300100109 | C19: 46328 | F19: =+(E19-D19)*24 -> 0
A20: LastName, FirstName | B20: 146300100109 | C20: 46329 | F20: =+(E20-D20)*24 -> 0
A21: LastName, FirstName | B21: 146300100109 | C21: 46329 | F21: =+(E21-D21)*24 -> 0
A22: LastName, FirstName | B22: 146300100109 | C22: 46329 | F22: =+(E22-D22)*24 -> 0
A23: LastName, FirstName | B23: 146300100109 | C23: 46329 | F23: =+(E23-D23)*24 -> 0
... A52: LastName, FirstName | B52: 146300100109 | C52: 46332 | F52: =+(E52-D52)*24 -> 0
A53: LastName, FirstName | C53: 46332 | F53: =+(E53-D53)*24 -> 0
A54: LastName, FirstName | C54: 46332 | F54: =+(E54-D54)*24 -> 0
A55: LastName, FirstName | C55: 46332 | F55: =+(E55-D55)*24 -> 0
A56: LastName, FirstName | C56: 46333 | D56: 0.35416667 | E56: 0.6875 | F56: =+(E56-D56)*24 -> 8 | G56: 9O Off | H56: HO (Public) Holiday | J56: Weekend / Wochenende
A57: LastName, FirstName | C57: 46333
A58: LastName, FirstName | C58: 46333 | F58: =+(E58-D58)*24 -> 0
A59: LastName, FirstName | C59: 46333 | F59: =+(E59-D59)*24 -> 0
A60: LastName, FirstName | C60: 46333 | F60: =+(E60-D60)*24 -> 0
A61: LastName, FirstName | C61: 46333 | F61: =+(E61-D61)*24 -> 0
A62: LastName, FirstName | C62: 46333 | F62: =+(E62-D62)*24 -> 0
A63: LastName, FirstName | C63: 46333 | F63: =+(E63-D63)*24 -> 0
A64: LastName, FirstName | C64: 46333 | F64: =+(E64-D64)*24 -> 0
A65: LastName, FirstName | C65: 46334 | D65: 0.35416667 | E65: 0.6875 | F65: =+(E65-D65)*24 -> 8 | G65: 9O Off | H65: HO (Public) Holiday | J65: Weekend / Wochenende
A66: LastName, FirstName | C66: 46334 | F66: =+(E66-D66)*24 -> 0
A67: LastName, FirstName | C67: 46334 | F67: =+(E67-D67)*24 -> 0
A68: LastName, FirstName | C68: 46334 | F68: =+(E68-D68)*24 -> 0
...

Sheet 12
A1: Name | B1: PSP-Element | C1: Date TT.MM.JJJJ | D1: from hh:mm | E1: to hh:mm | F1: hours autom. calculated | G1: Project (mandatory) | H1: Topic (mandatory) | I1: Task Group (optional) | J1: Description (optional) | K1: Task ID
A2: LastName, FirstName | B2: 146300100109 | C2: 46357 | F2: =+(E2-D2)*24 -> 0
A3: LastName, FirstName | B3: 146300100109 | C3: 46357 | F3: =+(E3-D3)*24 -> 0
A4: LastName, FirstName | B4: 146300100109 | C4: 46357 | F4: =+(E4-D4)*24 -> 0
A5: LastName, FirstName | B5: 146300100109 | C5: 46357 | F5: =+(E5-D5)*24 -> 0
A6: LastName, FirstName | B6: 146300100109 | C6: 46357 | F6: =+(E6-D6)*24 -> 0
A7: LastName, FirstName | B7: 146300100109 | C7: 46357 | F7: =+(E7-D7)*24 -> 0
A8: LastName, FirstName | B8: 146300100109 | C8: 46357 | F8: =+(E8-D8)*24 -> 0
A9: LastName, FirstName | C9: 46357 | F9: =+(E9-D9)*24 -> 0
A10: LastName, FirstName | B10: 146300100109 | C10: 46357 | F10: =+(E10-D10)*24 -> 0
A11: LastName, FirstName | B11: 146300100109 | C11: 46358 | F11: =+(E11-D11)*24 -> 0
A12: LastName, FirstName | B12: 146300100109 | C12: 46358 | F12: =+(E12-D12)*24 -> 0
A13: LastName, FirstName | B13: 146300100109 | C13: 46358 | F13: =+(E13-D13)*24 -> 0
A14: LastName, FirstName | B14: 146300100109 | C14: 46358 | F14: =+(E14-D14)*24 -> 0
A15: LastName, FirstName | B15: 146300100109 | C15: 46358 | F15: =+(E15-D15)*24 -> 0
A16: LastName, FirstName | B16: 146300100109 | C16: 46358 | F16: =+(E16-D16)*24 -> 0
A17: LastName, FirstName | B17: 146300100109 | C17: 46358 | F17: =+(E17-D17)*24 -> 0
A18: LastName, FirstName | B18: 146300100109 | C18: 46358 | F18: =+(E18-D18)*24 -> 0
A19: LastName, FirstName | B19: 146300100109 | C19: 46358 | F19: =+(E19-D19)*24 -> 0
A20: LastName, FirstName | B20: 146300100109 | C20: 46359 | F20: =+(E20-D20)*24 -> 0
A21: LastName, FirstName | B21: 146300100109 | C21: 46359 | F21: =+(E21-D21)*24 -> 0
... A37: LastName, FirstName | B37: 146300100109 | C37: 46360 | F37: =+(E37-D37)*24 -> 0
A38: LastName, FirstName | B38: 146300100109 | C38: 46361 | D38: 0.35416667 | E38: 0.6875 | F38: =+(E38-D38)*24 -> 8 | G38: 9O Off | H38: HO (Public) Holiday | J38: Weekend / Wochenende
A39: LastName, FirstName | B39: 146300100109 | C39: 46361
A40: LastName, FirstName | B40: 146300100109 | C40: 46361 | F40: =+(E40-D40)*24 -> 0
A41: LastName, FirstName | B41: 146300100109 | C41: 46361 | F41: =+(E41-D41)*24 -> 0
A42: LastName, FirstName | B42: 146300100109 | C42: 46361 | F42: =+(E42-D42)*24 -> 0
A43: LastName, FirstName | B43: 146300100109 | C43: 46361 | F43: =+(E43-D43)*24 -> 0
A44: LastName, FirstName | B44: 146300100109 | C44: 46361 | F44: =+(E44-D44)*24 -> 0
A45: LastName, FirstName | B45: 146300100109 | C45: 46361 | F45: =+(E45-D45)*24 -> 0
A46: LastName, FirstName | B46: 146300100109 | C46: 46361 | F46: =+(E46-D46)*24 -> 0
A47: LastName, FirstName | B47: 146300100109 | C47: 46362 | D47: 0.35416667 | E47: 0.6875 | F47: =+(E47-D47)*24 -> 8 | G47: 9O Off | H47: HO (Public) Holiday | J47: Weekend / Wochenende
A48: LastName, FirstName | B48: 146300100109 | C48: 46362 | F48: =+(E48-D48)*24 -> 0
A49: LastName, FirstName | B49: 146300100109 | C49: 46362 | F49: =+(E49-D49)*24 -> 0
A50: LastName, FirstName | B50: 146300100109 | C50: 46362 | F50: =+(E50-D50)*24 -> 0
A51: LastName, FirstName | B51: 146300100109 | C51: 46362 | F51: =+(E51-D51)*24 -> 0
A52: LastName, FirstName | B52: 146300100109 | C52: 46362 | F52: =+(E52-D52)*24 -> 0
A53: LastName, FirstName | C53: 46362 | F53: =+(E53-D53)*24 -> 0
A54: LastName, FirstName | C54: 46362 | F54: =+(E54-D54)*24 -> 0
A55: LastName, FirstName | C55: 46362 | F55: =+(E55-D55)*24 -> 0
...

Sheet Overview
A1: Month | B1: 1C RDM RDM Classic | C1: 2C RDM C RDM Cloud Ready | D1: 9M Misc | E1: 9O Off (incl. VA, IL, HO) | F1: Sum (hours) | G1: Sum (days) | H1: To be (hours) | I1: To be (days) | J1: +/- (hours) | K1: Vacation (hours) | L1: Vacation (days)
A2: 01 | B2: ='01'!$F$301 -> 0 | C2: ='01'!$F$302 -> 0 | D2: ='01'!$F$303 -> 0 | E2: ='01'!$F$304 -> 0 | F2: =SUM(B2:E2) -> 0 | G2: =F2/$B$20 -> 0 | H2: =ROUND(I2*$B$19/$B$20,2) -> 248 | I2: 31 | J2: =F2-H2 -> -248 | K2: ='01'!$F$310 -> 0 | L2: =K2/$B$20 -> 0
A3: 02 | B3: ='02'!$F$292 -> 0 | C3: ='02'!$F$270 -> 0 | D3: ='02'!$F$271 -> 0 | E3: ='02'!$F$272 -> 0 | F3: =SUM(B3:E3) -> 0 | G3: =F3/$B$20 -> 0 | H3: =ROUND(I3*$B$19/$B$20,2) -> 224 | I3: 28 | J3: =F3-H3 -> -224 | K3: ='02'!$F$278 -> 0 | L3: =K3/$B$20 -> 0
A4: 03 | B4: ='03'!$F$301 -> 0 | C4: ='03'!$F$302 -> 0 | D4: ='02'!$F$271 -> 0 | E4: ='02'!$F$272 -> 0 | F4: =SUM(B4:E4) -> 0 | G4: =F4/$B$20 -> 0 | H4: =ROUND(I4*$B$19/$B$20,2) -> 248 | I4: 31 | J4: =F4-H4 -> -248 | K4: ='03'!$F$310 -> 0 | L4: =K4/$B$20 -> 0
A5: 04 | B5: ='04'!$F$301 -> 0 | C5: ='04'!$F$302 -> 0 | D5: ='02'!$F$271 -> 0 | E5: ='02'!$F$272 -> 0 | F5: =SUM(B5:E5) -> 0 | G5: =F5/$B$20 -> 0 | H5: =ROUND(I5*$B$19/$B$20,2) -> 240 | I5: 30 | J5: =F5-H5 -> -240 | K5: ='04'!$F$310 -> 0 | L5: =K5/$B$20 -> 0
A6: 05 | B6: ='05'!$F$301 -> 0 | C6: ='05'!$F$302 -> 0 | D6: ='02'!$F$271 -> 0 | E6: ='02'!$F$272 -> 0 | F6: =SUM(B6:E6) -> 0 | G6: =F6/$B$20 -> 0 | H6: =ROUND(I6*$B$19/$B$20,2) -> 248 | I6: 31 | J6: =F6-H6 -> -248 | K6: ='05'!$F$310 -> 0 | L6: =K6/$B$20 -> 0
A7: 06 | B7: ='06'!$F$301 -> 0 | C7: ='06'!$F$302 -> 0 | D7: ='02'!$F$271 -> 0 | E7: ='02'!$F$272 -> 0 | F7: =SUM(B7:E7) -> 0 | G7: =F7/$B$20 -> 0 | H7: =ROUND(I7*$B$19/$B$20,2) -> 240 | I7: 30 | J7: =F7-H7 -> -240 | K7: ='06'!$F$310 -> 0 | L7: =K7/$B$20 -> 0
A8: 07 | B8: ='07'!$F$301 -> 0 | C8: ='07'!$F$302 -> 0 | D8: ='02'!$F$271 -> 0 | E8: ='02'!$F$272 -> 0 | F8: =SUM(B8:E8) -> 0 | G8: =F8/$B$20 -> 0 | H8: =ROUND(I8*$B$19/$B$20,2) -> 248 | I8: 31 | J8: =F8-H8 -> -248 | K8: ='07'!$F$310 -> 0 | L8: =K8/$B$20 -> 0
A9: 08 | B9: ='08'!$F$301 -> 0 | C9: ='08'!$F$302 -> 0 | D9: ='02'!$F$271 -> 0 | E9: ='02'!$F$272 -> 0 | F9: =SUM(B9:E9) -> 0 | G9: =F9/$B$20 -> 0 | H9: =ROUND(I9*$B$19/$B$20,2) -> 248 | I9: 31 | J9: =F9-H9 -> -248 | K9: ='08'!$F$310 -> 0 | L9: =K9/$B$20 -> 0
A10: 09 | B10: ='09'!$F$301 -> 0 | C10: ='09'!$F$302 -> 0 | D10: ='02'!$F$271 -> 0 | E10: ='02'!$F$272 -> 0 | F10: =SUM(B10:E10) -> 0 | G10: =F10/$B$20 -> 0 | H10: =ROUND(I10*$B$19/$B$20,2) -> 240 | I10: 30 | J10: =F10-H10 -> -240 | K10: ='09'!$F$310 -> 0 | L10: =K10/$B$20 -> 0
A11: 10 | B11: ='10'!$F$301 -> 0 | C11: ='10'!$F$302 -> 0 | D11: ='02'!$F$271 -> 0 | E11: ='02'!$F$272 -> 0 | F11: =SUM(B11:E11) -> 0 | G11: =F11/$B$20 -> 0 | H11: =ROUND(I11*$B$19/$B$20,2) -> 248 | I11: 31 | J11: =F11-H11 -> -248 | K11: ='10'!$F$310 -> 0 | L11: =K11/$B$20 -> 0
A12: 11 | B12: ='11'!$F$301 -> 0 | C12: ='11'!$F$302 -> 0 | D12: ='02'!$F$271 -> 0 | E12: ='02'!$F$272 -> 0 | F12: =SUM(B12:E12) -> 0 | G12: =F12/$B$20 -> 0 | H12: =ROUND(I12*$B$19/$B$20,2) -> 240 | I12: 30 | J12: =F12-H12 -> -240 | K12: ='11'!$F$310 -> 0 | L12: =K12/$B$20 -> 0
A13: 12 | B13: ='12'!$F$301 -> 0 | C13: ='12'!$F$302 -> 0 | D13: ='02'!$F$271 -> 0 | E13: ='02'!$F$272 -> 0 | F13: =SUM(B13:E13) -> 0 | G13: =F13/$B$20 -> 0 | H13: =ROUND(I13*$B$19/$B$20,2) -> 248 | I13: 31 | J13: =F13-H13 -> -248 | K13: ='12'!$F$310 -> 0 | L13: =K13/$B$20 -> 0
A15: Sum | B15: =SUM(B2:B13) -> 0 | C15: =SUM(C2:C13) -> 0 | D15: =SUM(D2:D13) -> 0 | E15: =SUM(E2:E13) -> 0 | F15: =SUM(F2:F13) -> 0 | G15: =SUM(G2:G13) -> 0 | H15: =SUM(H2:H13) -> 2920 | I15: =SUM(I2:I13) -> 365 | ... L15: =SUM(L2:L13) -> 0
K16: Left | L16: =B24-L15 -> 28
A18: hours/month | B18: =B19*4.33 -> 173.2
A19: hour/week | B19: 40
A20: days/week | B20: 5
A21: hours/day | B21: =B19/B20 -> 8
A23: Year | B23: 2026
A24: Vacation (days) | B24: 28
A26: Last Name | B26: Erlenbusch
A27: First Name | B27: Maximilian

Sheet Calendar
A1: 2026
A3: JANUAR | I3: FEBRUAR | Q3: MÄRZ | Y3: APRIL
A4: Mo | B4: Di | C4: Mi | D4: Do | E4: Fr | F4: Sa | G4: So | I4: Mo | J4: Di | K4: Mi | L4: Do | M4: Fr | N4: Sa | O4: So | Q4: Mo | R4: Di | S4: Mi | T4: Do | U4: Fr | V4: Sa | W4: So | Y4: Mo | Z4: Di | AA4: Mi | AB4: Do | AC4: Fr | AD4: Sa | AE4: So
D5: 1 | E5: 2 | F5: 3 | G5: 4 | O5: 1 | W5: 1 | AA5: 1 | AB5: 2 | AC5: 3 | AD5: 4 | AE5: 5
A6: 5 | B6: 6 | C6: 7 | D6: 8 | E6: 9 | F6: 10 | G6: 11 | I6: 2 | J6: 3 | K6: 4 | L6: 5 | M6: 6 | N6: 7 | O6: 8 | Q6: 2 | R6: 3 | S6: 4 | T6: 5 | U6: 6 | V6: 7 | W6: 8 | Y6: 6 | Z6: 7 | AA6: 8 | AB6: 9 | AC6: 10 | AD6: 11 | AE6: 12
A7: 12 | B7: 13 | C7: 14 | D7: 15 | E7: 16 | F7: 17 | G7: 18 | I7: 9 | J7: 10 | K7: 11 | L7: 12 | M7: 13 | N7: 14 | O7: 15 | Q7: 9 | R7: 10 | S7: 11 | T7: 12 | U7: 13 | V7: 14 | W7: 15 | Y7: 13 | Z7: 14 | AA7: 15 | AB7: 16 | AC7: 17 | AD7: 18 | AE7: 19
A8: 19 | B8: 20 | C8: 21 | D8: 22 | E8: 23 | F8: 24 | G8: 25 | I8: 16 | J8: 17 | K8: 18 | L8: 19 | M8: 20 | N8: 21 | O8: 22 | Q8: 16 | R8: 17 | S8: 18 | T8: 19 | U8: 20 | V8: 21 | W8: 22 | Y8: 20 | Z8: 21 | AA8: 22 | AB8: 23 | AC8: 24 | AD8: 25 | AE8: 26
A9: 26 | B9: 27 | C9: 28 | D9: 29 | E9: 30 | F9: 31 | I9: 23 | J9: 24 | K9: 25 | L9: 26 | M9: 27 | N9: 28 | Q9: 23 | R9: 24 | S9: 25 | T9: 26 | U9: 27 | V9: 28 | W9: 29 | Y9: 27 | Z9: 28 | AA9: 29 | AB9: 30
Q10: 30 | R10: 31
A12: MAI | I12: JUNI | Q12: JULI | Y12: AUGUST
A13: Mo | B13: Di | C13: Mi | D13: Do | E13: Fr | F13: Sa | G13: So | I13: Mo | J13: Di | K13: Mi | L13: Do | M13: Fr | N13: Sa | O13: So | Q13: Mo | R13: Di | S13: Mi | T13: Do | U13: Fr | V13: Sa | W13: So | Y13: Mo | Z13: Di | AA13: Mi | AB13: Do | AC13: Fr | AD13: Sa | AE13: So
E14: 1 | F14: 2 | G14: 3 | I14: 1 | J14: 2 | K14: 3 | L14: 4 | M14: 5 | N14: 6 | O14: 7 | S14: 1 | T14: 2 | U14: 3 | V14: 4 | W14: 5 | AD14: 1 | AE14: 2
A15: 4 | B15: 5 | C15: 6 | D15: 7 | E15: 8 | F15: 9 | G15: 10 | I15: 8 | J15: 9 | K15: 10 | L15: 11 | M15: 12 | N15: 13 | O15: 14 | Q15: 6 | R15: 7 | S15: 8 | T15: 9 | U15: 10 | V15: 11 | W15: 12 | Y15: 3 | Z15: 4 | AA15: 5 | AB15: 6 | AC15: 7 | AD15: 8 | AE15: 9
A16: 11 | B16: 12 | C16: 13 | D16: 14 | E16: 15 | F16: 16 | G16: 17 | I16: 15 | J16: 16 | K16: 17 | L16: 18 | M16: 19 | N16: 20 | O16: 21 | Q16: 13 | R16: 14 | S16: 15 | T16: 16 | U16: 17 | V16: 18 | W16: 19 | Y16: 10 | Z16: 11 | AA16: 12 | AB16: 13 | AC16: 14 | AD16: 15 | AE16: 16
